Workbook

Sheet Cómo usar
B1: Plantilla de gestión documental de PRL e instrucciones de trabajo
B2: REELEVO · gmvsolutions.es · Plantilla gratuita. Los datos que trae son un ejemplo ficticio: bórralos y pon los tuyos.
B4: Para qué sirve
B5: Saber, para cada trabajador y cada instrucción de PRL, de trabajo (IT), de calidad o política, si conoce la versión vigente, qué tiene pendiente y qué caduca. Es la tabla que en papel se descontrola: aquí no se rellena a mano, se calcula.
B7: Qué rellenas tú (celdas amarillas)
B8: 1. Instrucciones: una fila por instrucción, con su versión vigente (número entero: 1, 2, 3…), a quién afecta y cada cuántos meses hay que reciclarla (0 si no caduca).
B9: 2. Trabajadores: una fila por persona, con su puesto, turno y si es de ETT. Marca «No» en Activo cuando alguien se vaya; no borres la fila.
B10: 3. Acuses: una fila cada vez que alguien lee y acepta una versión. Es el registro: no se modifica, solo se añaden filas.
B12: Qué se calcula solo
B13: · Matriz: el estado de cada persona en cada instrucción. OK, Pendiente (no ha aceptado la versión vigente), Caducado (pasó su reciclaje), Caduca pronto (en los próximos 30 días) o «—» si no le afecta.
B14: · Resumen: combinaciones a controlar, pendientes, caducados y porcentaje al día. Los pendientes por persona salen en Trabajadores, y los pendientes por instrucción en Instrucciones.
B16: Cuando cambia una instrucción
... B30: Celda amarilla = la rellenas tú. Celda blanca o gris = fórmula, no la toques.

Sheet Resumen
A1: Resumen
A2: Se calcula solo a partir de Instrucciones, Trabajadores y Acuses.
B4: Fecha de referencia | C4: =TODAY() -> 46312 | D4: Por defecto, hoy. Escribe otra fecha para ver cómo estabas ese día (p. ej., el de una auditoría).
B6: Instrucciones registradas | C6: =COUNTA(Instrucciones!$A$5:$A$44) -> 8 | D6: Todas las que tienen código en la hoja Instrucciones.
B7: Trabajadores activos | C7: =COUNTIF(Matriz!$A$10:$A$129,"?*") -> 9 | D7: Los que tienen Activo distinto de «No».
B8: Personal de ETT activo | C8: =COUNTIFS(Trabajadores!$E$5:$E$124,"Sí",Trabajadores!$G$5:$G$124,"<>No") -> 2
B9: Combinaciones persona-instrucción a controlar | C9: =COUNTIF(Matriz!$D$10:$AQ$129,"OK")+COUNTIF(Matriz!$D$10:$AQ$129,"Pendiente")+COUNTIF(Matriz!$D$10:$AQ$129,"Caducado")+COUNTIF(Matriz!$D$10:$AQ$129,"Caduca pronto") -> 47 | D9: Cada una es algo que alguien tiene que poder demostrar. Crece mucho más deprisa que la plantilla.
B10: Al día | C10: =COUNTIF(Matriz!$D$10:$AQ$129,"OK")+COUNTIF(Matriz!$D$10:$AQ$129,"Caduca pronto") -> 24
B11: Pendientes (no han aceptado la versión vigente) | C11: =COUNTIF(Matriz!$D$10:$AQ$129,"Pendiente") -> 22 | D11: Cada revisión de una instrucción vuelve a dejar pendientes a todos sus afectados.
B12: Caducados (reciclaje vencido) | C12: =COUNTIF(Matriz!$D$10:$AQ$129,"Caducado") -> 1
B13: Caducan en los próximos 30 días | C13: =COUNTIF(Matriz!$D$10:$AQ$129,"Caduca pronto") -> 1
B14: % al día | C14: =IF(C9=0,"",C10/C9) -> 0.5106383 | D14: Objetivo: 100 % en las instrucciones de seguridad.
B17: ¿Te salen muchos pendientes cada vez que cambias una versión?
B18: Es normal: es aritmética, no falta de diligencia. Por qué la gestión documental se desborda con carpetas y Excel, y cómo se mantiene sola la lista de pendientes: gmvsolutions.es/blog/gestion-instrucciones-prl-e-it/

Sheet Instrucciones
A1: Instrucciones
A2: Una fila por instrucción. Versión vigente en número entero. Alcance: «Toda la plantilla» o «Por puesto» (y escribe los puestos separados por ;).
A4: Código | B4: Tipo | C4: Título | D4: Versión vigente | E4: Fecha de la versión | F4: Responsable | G4: Alcance | H4: Puestos afectados (separados por ;) | I4: Reciclaje (meses, 0 = no caduca) | J4: Afectados | K4: Pendientes | L4: Caducados | M4: % al día
A5: PRL-01 | B5: PRL | C5: Uso de EPI en planta | D5: 3 | E5: 46266 | F5: Prevención | G5: Toda la plantilla | I5: 12 | J5: =IF($A5="","",COUNTIF(Matriz!$D$10:$D$129,"OK")+COUNTIF(Matriz!$D$10:$D$129,"Pendiente")+COUNTIF(Matriz!$D$10:$D$129,"Caducado")+COUNTIF(Matriz!$D$10:$D$129,"Caduca pronto")) -> 9 | K5: =IF($A5="","",COUNTIF(Matriz!$D$10:$D$129,"Pendiente")) -> 3 | L5: =IF($A5="","",COUNTIF(Matriz!$D$10:$D$129,"Caducado")) -> 0 | M5: =IF(OR($A5="",N(J5)=0),"",(COUNTIF(Matriz!$D$10:$D$129,"OK")+COUNTIF(Matriz!$D$10:$D$129,"Caduca pronto"))/J5) -> 0.66666667
A6: PRL-02 | B6: PRL | C6: Conducción de carretillas elevadoras | D6: 2 | E6: 46188 | F6: Prevención | G6: Por puesto | H6: Logística; Almacén | I6: 24 | J6: =IF($A6="","",COUNTIF(Matriz!$E$10:$E$129,"OK")+COUNTIF(Matriz!$E$10:$E$129,"Pendiente")+COUNTIF(Matriz!$E$10:$E$129,"Caducado")+COUNTIF(Matriz!$E$10:$E$129,"Caduca pronto")) -> 2 | K6: =IF($A6="","",COUNTIF(Matriz!$E$10:$E$129,"Pendiente")) -> 0 | L6: =IF($A6="","",COUNTIF(Matriz!$E$10:$E$129,"Caducado")) -> 1 | M6: =IF(OR($A6="",N(J6)=0),"",(COUNTIF(Matriz!$E$10:$E$129,"OK")+COUNTIF(Matriz!$E$10:$E$129,"Caduca pronto"))/J6) -> 0.5
A7: PRL-03 | B7: PRL | C7: Bloqueo y consignación de energías (LOTO) | D7: 1 | E7: 46091 | F7: Prevención | G7: Por puesto | H7: Mantenimiento; Producción | I7: 12 | J7: =IF($A7="","",COUNTIF(Matriz!$F$10:$F$129,"OK")+COUNTIF(Matriz!$F$10:$F$129,"Pendiente")+COUNTIF(Matriz!$F$10:$F$129,"Caducado")+COUNTIF(Matriz!$F$10:$F$129,"Caduca pronto")) -> 6 | K7: =IF($A7="","",COUNTIF(Matriz!$F$10:$F$129,"Pendiente")) -> 3 | L7: =IF($A7="","",COUNTIF(Matriz!$F$10:$F$129,"Caducado")) -> 0 | M7: =IF(OR($A7="",N(J7)=0),"",(COUNTIF(Matriz!$F$10:$F$129,"OK")+COUNTIF(Matriz!$F$10:$F$129,"Caduca pronto"))/J7) -> 0.5
A8: PRL-04 | B8: PRL | C8: Manipulación de productos químicos | D8: 2 | E8: 46254 | F8: Prevención | G8: Por puesto | H8: Producción | I8: 0 | J8: =IF($A8="","",COUNTIF(Matriz!$G$10:$G$129,"OK")+COUNTIF(Matriz!$G$10:$G$129,"Pendiente")+COUNTIF(Matriz!$G$10:$G$129,"Caducado")+COUNTIF(Matriz!$G$10:$G$129,"Caduca pronto")) -> 5 | K8: =IF($A8="","",COUNTIF(Matriz!$G$10:$G$129,"Pendiente")) -> 3 | L8: =IF($A8="","",COUNTIF(Matriz!$G$10:$G$129,"Caducado")) -> 0 | M8: =IF(OR($A8="",N(J8)=0),"",(COUNTIF(Matriz!$G$10:$G$129,"OK")+COUNTIF(Matriz!$G$10:$G$129,"Caduca pronto"))/J8) -> 0.4
A9: IT-10 | B9: IT | C9: Arranque y ajuste de la prensa 2 | D9: 4 | E9: 46296 | F9: Ingeniería | G9: Por puesto | H9: Producción | I9: 0 | J9: =IF($A9="","",COUNTIF(Matriz!$H$10:$H$129,"OK")+COUNTIF(Matriz!$H$10:$H$129,"Pendiente")+COUNTIF(Matriz!$H$10:$H$129,"Caducado")+COUNTIF(Matriz!$H$10:$H$129,"Caduca pronto")) -> 5 | K9: =IF($A9="","",COUNTIF(Matriz!$H$10:$H$129,"Pendiente")) -> 4 | L9: =IF($A9="","",COUNTIF(Matriz!$H$10:$H$129,"Caducado")) -> 0 | M9: =IF(OR($A9="",N(J9)=0),"",(COUNTIF(Matriz!$H$10:$H$129,"OK")+COUNTIF(Matriz!$H$10:$H$129,"Caduca pronto"))/J9) -> 0.2
A10: IT-11 | B10: IT | C10: Cambio de formato en línea de corte | D10: 2 | E10: 46208 | F10: Ingeniería | G10: Por puesto | H10: Producción | I10: 0 | J10: =IF($A10="","",COUNTIF(Matriz!$I$10:$I$129,"OK")+COUNTIF(Matriz!$I$10:$I$129,"Pendiente")+COUNTIF(Matriz!$I$10:$I$129,"Caducado")+COUNTIF(Matriz!$I$10:$I$129,"Caduca pronto")) -> 5 | K10: =IF($A10="","",COUNTIF(Matriz!$I$10:$I$129,"Pendiente")) -> 1 | L10: =IF($A10="","",COUNTIF(Matriz!$I$10:$I$129,"Caducado")) -> 0 | M10: =IF(OR($A10="",N(J10)=0),"",(COUNTIF(Matriz!$I$10:$I$129,"OK")+COUNTIF(Matriz!$I$10:$I$129,"Caduca pronto"))/J10) -> 0.8
A11: CAL-01 | B11: Calidad | C11: Control de primera pieza | D11: 1 | E11: 46144 | F11: Calidad | G11: Por puesto | H11: Producción; Calidad | I11: 0 | J11: =IF($A11="","",COUNTIF(Matriz!$J$10:$J$129,"OK")+COUNTIF(Matriz!$J$10:$J$129,"Pendiente")+COUNTIF(Matriz!$J$10:$J$129,"Caducado")+COUNTIF(Matriz!$J$10:$J$129,"Caduca pronto")) -> 6 | K11: =IF($A11="","",COUNTIF(Matriz!$J$10:$J$129,"Pendiente")) -> 4 | L11: =IF($A11="","",COUNTIF(Matriz!$J$10:$J$129,"Caducado")) -> 0 | M11: =IF(OR($A11="",N(J11)=0),"",(COUNTIF(Matriz!$J$10:$J$129,"OK")+COUNTIF(Matriz!$J$10:$J$129,"Caduca pronto"))/J11) -> 0.33333333
A12: POL-01 | B12: Política | C12: Política de seguridad y salud | D12: 1 | E12: 46037 | F12: Dirección | G12: Toda la plantilla | I12: 0 | J12: =IF($A12="","",COUNTIF(Matriz!$K$10:$K$129,"OK")+COUNTIF(Matriz!$K$10:$K$129,"Pendiente")+COUNTIF(Matriz!$K$10:$K$129,"Caducado")+COUNTIF(Matriz!$K$10:$K$129,"Caduca pronto")) -> 9 | K12: =IF($A12="","",COUNTIF(Matriz!$K$10:$K$129,"Pendiente")) -> 4 | L12: =IF($A12="","",COUNTIF(Matriz!$K$10:$K$129,"Caducado")) -> 0 | M12: =IF(OR($A12="",N(J12)=0),"",(COUNTIF(Matriz!$K$10:$K$129,"OK")+COUNTIF(Matriz!$K$10:$K$129,"Caduca pronto"))/J12) -> 0.55555556
J13: =IF($A13="","",COUNTIF(Matriz!$L$10:$L$129,"OK")+COUNTIF(Matriz!$L$10:$L$129,"Pendiente")+COUNTIF(Matriz!$L$10:$L$129,"Caducado")+COUNTIF(Matriz!$L$10:$L$129,"Caduca pronto")) | K13: =IF($A13="","",COUNTIF(Matriz!$L$10:$L$129,"Pendiente")) | L13: =IF($A13="","",COUNTIF(Matriz!$L$10:$L$129,"Caducado")) | M13: =IF(OR($A13="",N(J13)=0),"",(COUNTIF(Matriz!$L$10:$L$129,"OK")+COUNTIF(Matriz!$L$10:$L$129,"Caduca pronto"))/J13)
J14: =IF($A14="","",COUNTIF(Matriz!$M$10:$M$129,"OK")+COUNTIF(Matriz!$M$10:$M$129,"Pendiente")+COUNTIF(Matriz!$M$10:$M$129,"Caducado")+COUNTIF(Matriz!$M$10:$M$129,"Caduca pronto")) | K14: =IF($A14="","",COUNTIF(Matriz!$M$10:$M$129,"Pendiente")) | L14: =IF($A14="","",COUNTIF(Matriz!$M$10:$M$129,"Caducado")) | M14: =IF(OR($A14="",N(J14)=0),"",(COUNTIF(Matriz!$M$10:$M$129,"OK")+COUNTIF(Matriz!$M$10:$M$129,"Caduca pronto"))/J14)
J15: =IF($A15="","",COUNTIF(Matriz!$N$10:$N$129,"OK")+COUNTIF(Matriz!$N$10:$N$129,"Pendiente")+COUNTIF(Matriz!$N$10:$N$129,"Caducado")+COUNTIF(Matriz!$N$10:$N$129,"Caduca pronto")) | K15: =IF($A15="","",COUNTIF(Matriz!$N$10:$N$129,"Pendiente")) | L15: =IF($A15="","",COUNTIF(Matriz!$N$10:$N$129,"Caducado")) | M15: =IF(OR($A15="",N(J15)=0),"",(COUNTIF(Matriz!$N$10:$N$129,"OK")+COUNTIF(Matriz!$N$10:$N$129,"Caduca pronto"))/J15)
J16: =IF($A16="","",COUNTIF(Matriz!$O$10:$O$129,"OK")+COUNTIF(Matriz!$O$10:$O$129,"Pendiente")+COUNTIF(Matriz!$O$10:$O$129,"Caducado")+COUNTIF(Matriz!$O$10:$O$129,"Caduca pronto")) | K16: =IF($A16="","",COUNTIF(Matriz!$O$10:$O$129,"Pendiente")) | L16: =IF($A16="","",COUNTIF(Matriz!$O$10:$O$129,"Caducado")) | M16: =IF(OR($A16="",N(J16)=0),"",(COUNTIF(Matriz!$O$10:$O$129,"OK")+COUNTIF(Matriz!$O$10:$O$129,"Caduca pronto"))/J16)
J17: =IF($A17="","",COUNTIF(Matriz!$P$10:$P$129,"OK")+COUNTIF(Matriz!$P$10:$P$129,"Pendiente")+COUNTIF(Matriz!$P$10:$P$129,"Caducado")+COUNTIF(Matriz!$P$10:$P$129,"Caduca pronto")) | K17: =IF($A17="","",COUNTIF(Matriz!$P$10:$P$129,"Pendiente")) | L17: =IF($A17="","",COUNTIF(Matriz!$P$10:$P$129,"Caducado")) | M17: =IF(OR($A17="",N(J17)=0),"",(COUNTIF(Matriz!$P$10:$P$129,"OK")+COUNTIF(Matriz!$P$10:$P$129,"Caduca pronto"))/J17)
J18: =IF($A18="","",COUNTIF(Matriz!$Q$10:$Q$129,"OK")+COUNTIF(Matriz!$Q$10:$Q$129,"Pendiente")+COUNTIF(Matriz!$Q$10:$Q$129,"Caducado")+COUNTIF(Matriz!$Q$10:$Q$129,"Caduca pronto")) | K18: =IF($A18="","",COUNTIF(Matriz!$Q$10:$Q$129,"Pendiente")) | L18: =IF($A18="","",COUNTIF(Matriz!$Q$10:$Q$129,"Caducado")) | M18: =IF(OR($A18="",N(J18)=0),"",(COUNTIF(Matriz!$Q$10:$Q$129,"OK")+COUNTIF(Matriz!$Q$10:$Q$129,"Caduca pronto"))/J18)
J19: =IF($A19="","",COUNTIF(Matriz!$R$10:$R$129,"OK")+COUNTIF(Matriz!$R$10:$R$129,"Pendiente")+COUNTIF(Matriz!$R$10:$R$129,"Caducado")+COUNTIF(Matriz!$R$10:$R$129,"Caduca pronto")) | K19: =IF($A19="","",COUNTIF(Matriz!$R$10:$R$129,"Pendiente")) | L19: =IF($A19="","",COUNTIF(Matriz!$R$10:$R$129,"Caducado")) | M19: =IF(OR($A19="",N(J19)=0),"",(COUNTIF(Matriz!$R$10:$R$129,"OK")+COUNTIF(Matriz!$R$10:$R$129,"Caduca pronto"))/J19)
J20: =IF($A20="","",COUNTIF(Matriz!$S$10:$S$129,"OK")+COUNTIF(Matriz!$S$10:$S$129,"Pendiente")+COUNTIF(Matriz!$S$10:$S$129,"Caducado")+COUNTIF(Matriz!$S$10:$S$129,"Caduca pronto")) | K20: =IF($A20="","",COUNTIF(Matriz!$S$10:$S$129,"Pendiente")) | L20: =IF($A20="","",COUNTIF(Matriz!$S$10:$S$129,"Caducado")) | M20: =IF(OR($A20="",N(J20)=0),"",(COUNTIF(Matriz!$S$10:$S$129,"OK")+COUNTIF(Matriz!$S$10:$S$129,"Caduca pronto"))/J20)
J21: =IF($A21="","",COUNTIF(Matriz!$T$10:$T$129,"OK")+COUNTIF(Matriz!$T$10:$T$129,"Pendiente")+COUNTIF(Matriz!$T$10:$T$129,"Caducado")+COUNTIF(Matriz!$T$10:$T$129,"Caduca pronto")) | K21: =IF($A21="","",COUNTIF(Matriz!$T$10:$T$129,"Pendiente")) | L21: =IF($A21="","",COUNTIF(Matriz!$T$10:$T$129,"Caducado")) | M21: =IF(OR($A21="",N(J21)=0),"",(COUNTIF(Matriz!$T$10:$T$129,"OK")+COUNTIF(Matriz!$T$10:$T$129,"Caduca pronto"))/J21)
J22: =IF($A22="","",COUNTIF(Matriz!$U$10:$U$129,"OK")+COUNTIF(Matriz!$U$10:$U$129,"Pendiente")+COUNTIF(Matriz!$U$10:$U$129,"Caducado")+COUNTIF(Matriz!$U$10:$U$129,"Caduca pronto")) | K22: =IF($A22="","",COUNTIF(Matriz!$U$10:$U$129,"Pendiente")) | L22: =IF($A22="","",COUNTIF(Matriz!$U$10:$U$129,"Caducado")) | M22: =IF(OR($A22="",N(J22)=0),"",(COUNTIF(Matriz!$U$10:$U$129,"OK")+COUNTIF(Matriz!$U$10:$U$129,"Caduca pronto"))/J22)
J23: =IF($A23="","",COUNTIF(Matriz!$V$10:$V$129,"OK")+COUNTIF(Matriz!$V$10:$V$129,"Pendiente")+COUNTIF(Matriz!$V$10:$V$129,"Caducado")+COUNTIF(Matriz!$V$10:$V$129,"Caduca pronto")) | K23: =IF($A23="","",COUNTIF(Matriz!$V$10:$V$129,"Pendiente")) | L23: =IF($A23="","",COUNTIF(Matriz!$V$10:$V$129,"Caducado")) | M23: =IF(OR($A23="",N(J23)=0),"",(COUNTIF(Matriz!$V$10:$V$129,"OK")+COUNTIF(Matriz!$V$10:$V$129,"Caduca pronto"))/J23)
J24: =IF($A24="","",COUNTIF(Matriz!$W$10:$W$129,"OK")+COUNTIF(Matriz!$W$10:$W$129,"Pendiente")+COUNTIF(Matriz!$W$10:$W$129,"Caducado")+COUNTIF(Matriz!$W$10:$W$129,"Caduca pronto")) | K24: =IF($A24="","",COUNTIF(Matriz!$W$10:$W$129,"Pendiente")) | L24: =IF($A24="","",COUNTIF(Matriz!$W$10:$W$129,"Caducado")) | M24: =IF(OR($A24="",N(J24)=0),"",(COUNTIF(Matriz!$W$10:$W$129,"OK")+COUNTIF(Matriz!$W$10:$W$129,"Caduca pronto"))/J24)
J25: =IF($A25="","",COUNTIF(Matriz!$X$10:$X$129,"OK")+COUNTIF(Matriz!$X$10:$X$129,"Pendiente")+COUNTIF(Matriz!$X$10:$X$129,"Caducado")+COUNTIF(Matriz!$X$10:$X$129,"Caduca pronto")) | K25: =IF($A25="","",COUNTIF(Matriz!$X$10:$X$129,"Pendiente")) | L25: =IF($A25="","",COUNTIF(Matriz!$X$10:$X$129,"Caducado")) | M25: =IF(OR($A25="",N(J25)=0),"",(COUNTIF(Matriz!$X$10:$X$129,"OK")+COUNTIF(Matriz!$X$10:$X$129,"Caduca pronto"))/J25)
J26: =IF($A26="","",COUNTIF(Matriz!$Y$10:$Y$129,"OK")+COUNTIF(Matriz!$Y$10:$Y$129,"Pendiente")+COUNTIF(Matriz!$Y$10:$Y$129,"Caducado")+COUNTIF(Matriz!$Y$10:$Y$129,"Caduca pronto")) | K26: =IF($A26="","",COUNTIF(Matriz!$Y$10:$Y$129,"Pendiente")) | L26: =IF($A26="","",COUNTIF(Matriz!$Y$10:$Y$129,"Caducado")) | M26: =IF(OR($A26="",N(J26)=0),"",(COUNTIF(Matriz!$Y$10:$Y$129,"OK")+COUNTIF(Matriz!$Y$10:$Y$129,"Caduca pronto"))/J26)
J27: =IF($A27="","",COUNTIF(Matriz!$Z$10:$Z$129,"OK")+COUNTIF(Matriz!$Z$10:$Z$129,"Pendiente")+COUNTIF(Matriz!$Z$10:$Z$129,"Caducado")+COUNTIF(Matriz!$Z$10:$Z$129,"Caduca pronto")) | K27: =IF($A27="","",COUNTIF(Matriz!$Z$10:$Z$129,"Pendiente")) | L27: =IF($A27="","",COUNTIF(Matriz!$Z$10:$Z$129,"Caducado")) | M27: =IF(OR($A27="",N(J27)=0),"",(COUNTIF(Matriz!$Z$10:$Z$129,"OK")+COUNTIF(Matriz!$Z$10:$Z$129,"Caduca pronto"))/J27)
J28: =IF($A28="","",COUNTIF(Matriz!$AA$10:$AA$129,"OK")+COUNTIF(Matriz!$AA$10:$AA$129,"Pendiente")+COUNTIF(Matriz!$AA$10:$AA$129,"Caducado")+COUNTIF(Matriz!$AA$10:$AA$129,"Caduca pronto")) | K28: =IF($A28="","",COUNTIF(Matriz!$AA$10:$AA$129,"Pendiente")) | L28: =IF($A28="","",COUNTIF(Matriz!$AA$10:$AA$129,"Caducado")) | M28: =IF(OR($A28="",N(J28)=0),"",(COUNTIF(Matriz!$AA$10:$AA$129,"OK")+COUNTIF(Matriz!$AA$10:$AA$129,"Caduca pronto"))/J28)
J29: =IF($A29="","",COUNTIF(Matriz!$AB$10:$AB$129,"OK")+COUNTIF(Matriz!$AB$10:$AB$129,"Pendiente")+COUNTIF(Matriz!$AB$10:$AB$129,"Caducado")+COUNTIF(Matriz!$AB$10:$AB$129,"Caduca pronto")) | K29: =IF($A29="","",COUNTIF(Matriz!$AB$10:$AB$129,"Pendiente")) | L29: =IF($A29="","",COUNTIF(Matriz!$AB$10:$AB$129,"Caducado")) | M29: =IF(OR($A29="",N(J29)=0),"",(COUNTIF(Matriz!$AB$10:$AB$129,"OK")+COUNTIF(Matriz!$AB$10:$AB$129,"Caduca pronto"))/J29)
J30: =IF($A30="","",COUNTIF(Matriz!$AC$10:$AC$129,"OK")+COUNTIF(Matriz!$AC$10:$AC$129,"Pendiente")+COUNTIF(Matriz!$AC$10:$AC$129,"Caducado")+COUNTIF(Matriz!$AC$10:$AC$129,"Caduca pronto")) | K30: =IF($A30="","",COUNTIF(Matriz!$AC$10:$AC$129,"Pendiente")) | L30: =IF($A30="","",COUNTIF(Matriz!$AC$10:$AC$129,"Caducado")) | M30: =IF(OR($A30="",N(J30)=0),"",(COUNTIF(Matriz!$AC$10:$AC$129,"OK")+COUNTIF(Matriz!$AC$10:$AC$129,"Caduca pronto"))/J30)
J31: =IF($A31="","",COUNTIF(Matriz!$AD$10:$AD$129,"OK")+COUNTIF(Matriz!$AD$10:$AD$129,"Pendiente")+COUNTIF(Matriz!$AD$10:$AD$129,"Caducado")+COUNTIF(Matriz!$AD$10:$AD$129,"Caduca pronto")) | K31: =IF($A31="","",COUNTIF(Matriz!$AD$10:$AD$129,"Pendiente")) | L31: =IF($A31="","",COUNTIF(Matriz!$AD$10:$AD$129,"Caducado")) | M31: =IF(OR($A31="",N(J31)=0),"",(COUNTIF(Matriz!$AD$10:$AD$129,"OK")+COUNTIF(Matriz!$AD$10:$AD$129,"Caduca pronto"))/J31)
J32: =IF($A32="","",COUNTIF(Matriz!$AE$10:$AE$129,"OK")+COUNTIF(Matriz!$AE$10:$AE$129,"Pendiente")+COUNTIF(Matriz!$AE$10:$AE$129,"Caducado")+COUNTIF(Matriz!$AE$10:$AE$129,"Caduca pronto")) | K32: =IF($A32="","",COUNTIF(Matriz!$AE$10:$AE$129,"Pendiente")) | L32: =IF($A32="","",COUNTIF(Matriz!$AE$10:$AE$129,"Caducado")) | M32: =IF(OR($A32="",N(J32)=0),"",(COUNTIF(Matriz!$AE$10:$AE$129,"OK")+COUNTIF(Matriz!$AE$10:$AE$129,"Caduca pronto"))/J32)
J33: =IF($A33="","",COUNTIF(Matriz!$AF$10:$AF$129,"OK")+COUNTIF(Matriz!$AF$10:$AF$129,"Pendiente")+COUNTIF(Matriz!$AF$10:$AF$129,"Caducado")+COUNTIF(Matriz!$AF$10:$AF$129,"Caduca pronto")) | K33: =IF($A33="","",COUNTIF(Matriz!$AF$10:$AF$129,"Pendiente")) | L33: =IF($A33="","",COUNTIF(Matriz!$AF$10:$AF$129,"Caducado")) | M33: =IF(OR($A33="",N(J33)=0),"",(COUNTIF(Matriz!$AF$10:$AF$129,"OK")+COUNTIF(Matriz!$AF$10:$AF$129,"Caduca pronto"))/J33)
J34: =IF($A34="","",COUNTIF(Matriz!$AG$10:$AG$129,"OK")+COUNTIF(Matriz!$AG$10:$AG$129,"Pendiente")+COUNTIF(Matriz!$AG$10:$AG$129,"Caducado")+COUNTIF(Matriz!$AG$10:$AG$129,"Caduca pronto")) | K34: =IF($A34="","",COUNTIF(Matriz!$AG$10:$AG$129,"Pendiente")) | L34: =IF($A34="","",COUNTIF(Matriz!$AG$10:$AG$129,"Caducado")) | M34: =IF(OR($A34="",N(J34)=0),"",(COUNTIF(Matriz!$AG$10:$AG$129,"OK")+COUNTIF(Matriz!$AG$10:$AG$129,"Caduca pronto"))/J34)
J35: =IF($A35="","",COUNTIF(Matriz!$AH$10:$AH$129,"OK")+COUNTIF(Matriz!$AH$10:$AH$129,"Pendiente")+COUNTIF(Matriz!$AH$10:$AH$129,"Caducado")+COUNTIF(Matriz!$AH$10:$AH$129,"Caduca pronto")) | K35: =IF($A35="","",COUNTIF(Matriz!$AH$10:$AH$129,"Pendiente")) | L35: =IF($A35="","",COUNTIF(Matriz!$AH$10:$AH$129,"Caducado")) | M35: =IF(OR($A35="",N(J35)=0),"",(COUNTIF(Matriz!$AH$10:$AH$129,"OK")+COUNTIF(Matriz!$AH$10:$AH$129,"Caduca pronto"))/J35)
J36: =IF($A36="","",COUNTIF(Matriz!$AI$10:$AI$129,"OK")+COUNTIF(Matriz!$AI$10:$AI$129,"Pendiente")+COUNTIF(Matriz!$AI$10:$AI$129,"Caducado")+COUNTIF(Matriz!$AI$10:$AI$129,"Caduca pronto")) | K36: =IF($A36="","",COUNTIF(Matriz!$AI$10:$AI$129,"Pendiente")) | L36: =IF($A36="","",COUNTIF(Matriz!$AI$10:$AI$129,"Caducado")) | M36: =IF(OR($A36="",N(J36)=0),"",(COUNTIF(Matriz!$AI$10:$AI$129,"OK")+COUNTIF(Matriz!$AI$10:$AI$129,"Caduca pronto"))/J36)
J37: =IF($A37="","",COUNTIF(Matriz!$AJ$10:$AJ$129,"OK")+COUNTIF(Matriz!$AJ$10:$AJ$129,"Pendiente")+COUNTIF(Matriz!$AJ$10:$AJ$129,"Caducado")+COUNTIF(Matriz!$AJ$10:$AJ$129,"Caduca pronto")) | K37: =IF($A37="","",COUNTIF(Matriz!$AJ$10:$AJ$129,"Pendiente")) | L37: =IF($A37="","",COUNTIF(Matriz!$AJ$10:$AJ$129,"Caducado")) | M37: =IF(OR($A37="",N(J37)=0),"",(COUNTIF(Matriz!$AJ$10:$AJ$129,"OK")+COUNTIF(Matriz!$AJ$10:$AJ$129,"Caduca pronto"))/J37)
J38: =IF($A38="","",COUNTIF(Matriz!$AK$10:$AK$129,"OK")+COUNTIF(Matriz!$AK$10:$AK$129,"Pendiente")+COUNTIF(Matriz!$AK$10:$AK$129,"Caducado")+COUNTIF(Matriz!$AK$10:$AK$129,"Caduca pronto")) | K38: =IF($A38="","",COUNTIF(Matriz!$AK$10:$AK$129,"Pendiente")) | L38: =IF($A38="","",COUNTIF(Matriz!$AK$10:$AK$129,"Caducado")) | M38: =IF(OR($A38="",N(J38)=0),"",(COUNTIF(Matriz!$AK$10:$AK$129,"OK")+COUNTIF(Matriz!$AK$10:$AK$129,"Caduca pronto"))/J38)
J39: =IF($A39="","",COUNTIF(Matriz!$AL$10:$AL$129,"OK")+COUNTIF(Matriz!$AL$10:$AL$129,"Pendiente")+COUNTIF(Matriz!$AL$10:$AL$129,"Caducado")+COUNTIF(Matriz!$AL$10:$AL$129,"Caduca pronto")) | K39: =IF($A39="","",COUNTIF(Matriz!$AL$10:$AL$129,"Pendiente")) | L39: =IF($A39="","",COUNTIF(Matriz!$AL$10:$AL$129,"Caducado")) | M39: =IF(OR($A39="",N(J39)=0),"",(COUNTIF(Matriz!$AL$10:$AL$129,"OK")+COUNTIF(Matriz!$AL$10:$AL$129,"Caduca pronto"))/J39)
J40: =IF($A40="","",COUNTIF(Matriz!$AM$10:$AM$129,"OK")+COUNTIF(Matriz!$AM$10:$AM$129,"Pendiente")+COUNTIF(Matriz!$AM$10:$AM$129,"Caducado")+COUNTIF(Matriz!$AM$10:$AM$129,"Caduca pronto")) | K40: =IF($A40="","",COUNTIF(Matriz!$AM$10:$AM$129,"Pendiente")) | L40: =IF($A40="","",COUNTIF(Matriz!$AM$10:$AM$129,"Caducado")) | M40: =IF(OR($A40="",N(J40)=0),"",(COUNTIF(Matriz!$AM$10:$AM$129,"OK")+COUNTIF(Matriz!$AM$10:$AM$129,"Caduca pronto"))/J40)
J41: =IF($A41="","",COUNTIF(Matriz!$AN$10:$AN$129,"OK")+COUNTIF(Matriz!$AN$10:$AN$129,"Pendiente")+COUNTIF(Matriz!$AN$10:$AN$129,"Caducado")+COUNTIF(Matriz!$AN$10:$AN$129,"Caduca pronto")) | K41: =IF($A41="","",COUNTIF(Matriz!$AN$10:$AN$129,"Pendiente")) | L41: =IF($A41="","",COUNTIF(Matriz!$AN$10:$AN$129,"Caducado")) | M41: =IF(OR($A41="",N(J41)=0),"",(COUNTIF(Matriz!$AN$10:$AN$129,"OK")+COUNTIF(Matriz!$AN$10:$AN$129,"Caduca pronto"))/J41)
...

Sheet Trabajadores
A1: Trabajadores
A2: Una fila por persona. El puesto tiene que escribirse igual que en «Puestos afectados». Cuando alguien se va, Activo = No (no borres la fila).
A4: ID | B4: Nombre | C4: Puesto | D4: Turno | E4: ETT | F4: Fecha de alta | G4: Activo | H4: Pendientes | I4: Caducados | J4: Caducan pronto
A5: T001 | B5: Ana López | C5: Producción | D5: Mañana | E5: No | F5: 44256 | G5: Sí | H5: =IF(Matriz!$A$10="","",COUNTIF(Matriz!$D$10:$AQ$10,"Pendiente")) -> 0 | I5: =IF(Matriz!$A$10="","",COUNTIF(Matriz!$D$10:$AQ$10,"Caducado")) -> 0 | J5: =IF(Matriz!$A$10="","",COUNTIF(Matriz!$D$10:$AQ$10,"Caduca pronto")) -> 0
A6: T002 | B6: Carlos Ruiz | C6: Producción | D6: Tarde | E6: No | F6: 43724 | G6: Sí | H6: =IF(Matriz!$A$11="","",COUNTIF(Matriz!$D$11:$AQ$11,"Pendiente")) -> 4 | I6: =IF(Matriz!$A$11="","",COUNTIF(Matriz!$D$11:$AQ$11,"Caducado")) -> 0 | J6: =IF(Matriz!$A$11="","",COUNTIF(Matriz!$D$11:$AQ$11,"Caduca pronto")) -> 0
A7: T003 | B7: Marta Gil | C7: Producción | D7: Noche | E7: No | F7: 44935 | G7: Sí | H7: =IF(Matriz!$A$12="","",COUNTIF(Matriz!$D$12:$AQ$12,"Pendiente")) -> 4 | I7: =IF(Matriz!$A$12="","",COUNTIF(Matriz!$D$12:$AQ$12,"Caducado")) -> 0 | J7: =IF(Matriz!$A$12="","",COUNTIF(Matriz!$D$12:$AQ$12,"Caduca pronto")) -> 0
A8: T004 | B8: Luis Pardo | C8: Mantenimiento | D8: Mañana | E8: No | F8: 43222 | G8: Sí | H8: =IF(Matriz!$A$13="","",COUNTIF(Matriz!$D$13:$AQ$13,"Pendiente")) -> 0 | I8: =IF(Matriz!$A$13="","",COUNTIF(Matriz!$D$13:$AQ$13,"Caducado")) -> 0 | J8: =IF(Matriz!$A$13="","",COUNTIF(Matriz!$D$13:$AQ$13,"Caduca pronto")) -> 1
A9: T005 | B9: Sara Vidal | C9: Calidad | D9: Mañana | E9: No | F9: 44872 | G9: Sí | H9: =IF(Matriz!$A$14="","",COUNTIF(Matriz!$D$14:$AQ$14,"Pendiente")) -> 0 | I9: =IF(Matriz!$A$14="","",COUNTIF(Matriz!$D$14:$AQ$14,"Caducado")) -> 0 | J9: =IF(Matriz!$A$14="","",COUNTIF(Matriz!$D$14:$AQ$14,"Caduca pronto")) -> 0
A10: T006 | B10: Jorge Martín | C10: Logística | D10: Tarde | E10: No | F10: 43864 | G10: Sí | H10: =IF(Matriz!$A$15="","",COUNTIF(Matriz!$D$15:$AQ$15,"Pendiente")) -> 1 | I10: =IF(Matriz!$A$15="","",COUNTIF(Matriz!$D$15:$AQ$15,"Caducado")) -> 1 | J10: =IF(Matriz!$A$15="","",COUNTIF(Matriz!$D$15:$AQ$15,"Caduca pronto")) -> 0
A11: T007 | B11: Iván Castro | C11: Almacén | D11: Mañana | E11: No | F11: 45404 | G11: Sí | H11: =IF(Matriz!$A$16="","",COUNTIF(Matriz!$D$16:$AQ$16,"Pendiente")) -> 1 | I11: =IF(Matriz!$A$16="","",COUNTIF(Matriz!$D$16:$AQ$16,"Caducado")) -> 0 | J11: =IF(Matriz!$A$16="","",COUNTIF(Matriz!$D$16:$AQ$16,"Caduca pronto")) -> 0
A12: T008 | B12: Nerea Sanz | C12: Producción | D12: Noche | E12: Sí | F12: 46294 | G12: Sí | H12: =IF(Matriz!$A$17="","",COUNTIF(Matriz!$D$17:$AQ$17,"Pendiente")) -> 5 | I12: =IF(Matriz!$A$17="","",COUNTIF(Matriz!$D$17:$AQ$17,"Caducado")) -> 0 | J12: =IF(Matriz!$A$17="","",COUNTIF(Matriz!$D$17:$AQ$17,"Caduca pronto")) -> 0
A13: T009 | B13: Pablo Rey | C13: Producción | D13: Tarde | E13: Sí | F13: 46301 | G13: Sí | H13: =IF(Matriz!$A$18="","",COUNTIF(Matriz!$D$18:$AQ$18,"Pendiente")) -> 7 | I13: =IF(Matriz!$A$18="","",COUNTIF(Matriz!$D$18:$AQ$18,"Caducado")) -> 0 | J13: =IF(Matriz!$A$18="","",COUNTIF(Matriz!$D$18:$AQ$18,"Caduca pronto")) -> 0
A14: T010 | B14: Elena Mora | C14: Producción | D14: Mañana | E14: No | F14: 42898 | G14: No | H14: =IF(Matriz!$A$19="","",COUNTIF(Matriz!$D$19:$AQ$19,"Pendiente")) | I14: =IF(Matriz!$A$19="","",COUNTIF(Matriz!$D$19:$AQ$19,"Caducado")) | J14: =IF(Matriz!$A$19="","",COUNTIF(Matriz!$D$19:$AQ$19,"Caduca pronto"))
H15: =IF(Matriz!$A$20="","",COUNTIF(Matriz!$D$20:$AQ$20,"Pendiente")) | I15: =IF(Matriz!$A$20="","",COUNTIF(Matriz!$D$20:$AQ$20,"Caducado")) | J15: =IF(Matriz!$A$20="","",COUNTIF(Matriz!$D$20:$AQ$20,"Caduca pronto"))
H16: =IF(Matriz!$A$21="","",COUNTIF(Matriz!$D$21:$AQ$21,"Pendiente")) | I16: =IF(Matriz!$A$21="","",COUNTIF(Matriz!$D$21:$AQ$21,"Caducado")) | J16: =IF(Matriz!$A$21="","",COUNTIF(Matriz!$D$21:$AQ$21,"Caduca pronto"))
H17: =IF(Matriz!$A$22="","",COUNTIF(Matriz!$D$22:$AQ$22,"Pendiente")) | I17: =IF(Matriz!$A$22="","",COUNTIF(Matriz!$D$22:$AQ$22,"Caducado")) | J17: =IF(Matriz!$A$22="","",COUNTIF(Matriz!$D$22:$AQ$22,"Caduca pronto"))
H18: =IF(Matriz!$A$23="","",COUNTIF(Matriz!$D$23:$AQ$23,"Pendiente")) | I18: =IF(Matriz!$A$23="","",COUNTIF(Matriz!$D$23:$AQ$23,"Caducado")) | J18: =IF(Matriz!$A$23="","",COUNTIF(Matriz!$D$23:$AQ$23,"Caduca pronto"))
H19: =IF(Matriz!$A$24="","",COUNTIF(Matriz!$D$24:$AQ$24,"Pendiente")) | I19: =IF(Matriz!$A$24="","",COUNTIF(Matriz!$D$24:$AQ$24,"Caducado")) | J19: =IF(Matriz!$A$24="","",COUNTIF(Matriz!$D$24:$AQ$24,"Caduca pronto"))
H20: =IF(Matriz!$A$25="","",COUNTIF(Matriz!$D$25:$AQ$25,"Pendiente")) | I20: =IF(Matriz!$A$25="","",COUNTIF(Matriz!$D$25:$AQ$25,"Caducado")) | J20: =IF(Matriz!$A$25="","",COUNTIF(Matriz!$D$25:$AQ$25,"Caduca pronto"))
H21: =IF(Matriz!$A$26="","",COUNTIF(Matriz!$D$26:$AQ$26,"Pendiente")) | I21: =IF(Matriz!$A$26="","",COUNTIF(Matriz!$D$26:$AQ$26,"Caducado")) | J21: =IF(Matriz!$A$26="","",COUNTIF(Matriz!$D$26:$AQ$26,"Caduca pronto"))
H22: =IF(Matriz!$A$27="","",COUNTIF(Matriz!$D$27:$AQ$27,"Pendiente")) | I22: =IF(Matriz!$A$27="","",COUNTIF(Matriz!$D$27:$AQ$27,"Caducado")) | J22: =IF(Matriz!$A$27="","",COUNTIF(Matriz!$D$27:$AQ$27,"Caduca pronto"))
H23: =IF(Matriz!$A$28="","",COUNTIF(Matriz!$D$28:$AQ$28,"Pendiente")) | I23: =IF(Matriz!$A$28="","",COUNTIF(Matriz!$D$28:$AQ$28,"Caducado")) | J23: =IF(Matriz!$A$28="","",COUNTIF(Matriz!$D$28:$AQ$28,"Caduca pronto"))
H24: =IF(Matriz!$A$29="","",COUNTIF(Matriz!$D$29:$AQ$29,"Pendiente")) | I24: =IF(Matriz!$A$29="","",COUNTIF(Matriz!$D$29:$AQ$29,"Caducado")) | J24: =IF(Matriz!$A$29="","",COUNTIF(Matriz!$D$29:$AQ$29,"Caduca pronto"))
H25: =IF(Matriz!$A$30="","",COUNTIF(Matriz!$D$30:$AQ$30,"Pendiente")) | I25: =IF(Matriz!$A$30="","",COUNTIF(Matriz!$D$30:$AQ$30,"Caducado")) | J25: =IF(Matriz!$A$30="","",COUNTIF(Matriz!$D$30:$AQ$30,"Caduca pronto"))
H26: =IF(Matriz!$A$31="","",COUNTIF(Matriz!$D$31:$AQ$31,"Pendiente")) | I26: =IF(Matriz!$A$31="","",COUNTIF(Matriz!$D$31:$AQ$31,"Caducado")) | J26: =IF(Matriz!$A$31="","",COUNTIF(Matriz!$D$31:$AQ$31,"Caduca pronto"))
H27: =IF(Matriz!$A$32="","",COUNTIF(Matriz!$D$32:$AQ$32,"Pendiente")) | I27: =IF(Matriz!$A$32="","",COUNTIF(Matriz!$D$32:$AQ$32,"Caducado")) | J27: =IF(Matriz!$A$32="","",COUNTIF(Matriz!$D$32:$AQ$32,"Caduca pronto"))
H28: =IF(Matriz!$A$33="","",COUNTIF(Matriz!$D$33:$AQ$33,"Pendiente")) | I28: =IF(Matriz!$A$33="","",COUNTIF(Matriz!$D$33:$AQ$33,"Caducado")) | J28: =IF(Matriz!$A$33="","",COUNTIF(Matriz!$D$33:$AQ$33,"Caduca pronto"))
H29: =IF(Matriz!$A$34="","",COUNTIF(Matriz!$D$34:$AQ$34,"Pendiente")) | I29: =IF(Matriz!$A$34="","",COUNTIF(Matriz!$D$34:$AQ$34,"Caducado")) | J29: =IF(Matriz!$A$34="","",COUNTIF(Matriz!$D$34:$AQ$34,"Caduca pronto"))
H30: =IF(Matriz!$A$35="","",COUNTIF(Matriz!$D$35:$AQ$35,"Pendiente")) | I30: =IF(Matriz!$A$35="","",COUNTIF(Matriz!$D$35:$AQ$35,"Caducado")) | J30: =IF(Matriz!$A$35="","",COUNTIF(Matriz!$D$35:$AQ$35,"Caduca pronto"))
H31: =IF(Matriz!$A$36="","",COUNTIF(Matriz!$D$36:$AQ$36,"Pendiente")) | I31: =IF(Matriz!$A$36="","",COUNTIF(Matriz!$D$36:$AQ$36,"Caducado")) | J31: =IF(Matriz!$A$36="","",COUNTIF(Matriz!$D$36:$AQ$36,"Caduca pronto"))
H32: =IF(Matriz!$A$37="","",COUNTIF(Matriz!$D$37:$AQ$37,"Pendiente")) | I32: =IF(Matriz!$A$37="","",COUNTIF(Matriz!$D$37:$AQ$37,"Caducado")) | J32: =IF(Matriz!$A$37="","",COUNTIF(Matriz!$D$37:$AQ$37,"Caduca pronto"))
H33: =IF(Matriz!$A$38="","",COUNTIF(Matriz!$D$38:$AQ$38,"Pendiente")) | I33: =IF(Matriz!$A$38="","",COUNTIF(Matriz!$D$38:$AQ$38,"Caducado")) | J33: =IF(Matriz!$A$38="","",COUNTIF(Matriz!$D$38:$AQ$38,"Caduca pronto"))
H34: =IF(Matriz!$A$39="","",COUNTIF(Matriz!$D$39:$AQ$39,"Pendiente")) | I34: =IF(Matriz!$A$39="","",COUNTIF(Matriz!$D$39:$AQ$39,"Caducado")) | J34: =IF(Matriz!$A$39="","",COUNTIF(Matriz!$D$39:$AQ$39,"Caduca pronto"))
H35: =IF(Matriz!$A$40="","",COUNTIF(Matriz!$D$40:$AQ$40,"Pendiente")) | I35: =IF(Matriz!$A$40="","",COUNTIF(Matriz!$D$40:$AQ$40,"Caducado")) | J35: =IF(Matriz!$A$40="","",COUNTIF(Matriz!$D$40:$AQ$40,"Caduca pronto"))
H36: =IF(Matriz!$A$41="","",COUNTIF(Matriz!$D$41:$AQ$41,"Pendiente")) | I36: =IF(Matriz!$A$41="","",COUNTIF(Matriz!$D$41:$AQ$41,"Caducado")) | J36: =IF(Matriz!$A$41="","",COUNTIF(Matriz!$D$41:$AQ$41,"Caduca pronto"))
H37: =IF(Matriz!$A$42="","",COUNTIF(Matriz!$D$42:$AQ$42,"Pendiente")) | I37: =IF(Matriz!$A$42="","",COUNTIF(Matriz!$D$42:$AQ$42,"Caducado")) | J37: =IF(Matriz!$A$42="","",COUNTIF(Matriz!$D$42:$AQ$42,"Caduca pronto"))
H38: =IF(Matriz!$A$43="","",COUNTIF(Matriz!$D$43:$AQ$43,"Pendiente")) | I38: =IF(Matriz!$A$43="","",COUNTIF(Matriz!$D$43:$AQ$43,"Caducado")) | J38: =IF(Matriz!$A$43="","",COUNTIF(Matriz!$D$43:$AQ$43,"Caduca pronto"))
H39: =IF(Matriz!$A$44="","",COUNTIF(Matriz!$D$44:$AQ$44,"Pendiente")) | I39: =IF(Matriz!$A$44="","",COUNTIF(Matriz!$D$44:$AQ$44,"Caducado")) | J39: =IF(Matriz!$A$44="","",COUNTIF(Matriz!$D$44:$AQ$44,"Caduca pronto"))
H40: =IF(Matriz!$A$45="","",COUNTIF(Matriz!$D$45:$AQ$45,"Pendiente")) | I40: =IF(Matriz!$A$45="","",COUNTIF(Matriz!$D$45:$AQ$45,"Caducado")) | J40: =IF(Matriz!$A$45="","",COUNTIF(Matriz!$D$45:$AQ$45,"Caduca pronto"))
H41: =IF(Matriz!$A$46="","",COUNTIF(Matriz!$D$46:$AQ$46,"Pendiente")) | I41: =IF(Matriz!$A$46="","",COUNTIF(Matriz!$D$46:$AQ$46,"Caducado")) | J41: =IF(Matriz!$A$46="","",COUNTIF(Matriz!$D$46:$AQ$46,"Caduca pronto"))
...

Sheet Acuses
A1: Registro de acuses
A2: Una fila cada vez que alguien lee y acepta una versión. Solo se añaden filas; las antiguas son el histórico.
A4: ID trabajador | B4: Código instrucción | C4: Versión aceptada | D4: Fecha de acuse | E4: Test superado | F4: Vía | G4: Observaciones
A5: T001 | B5: PRL-01 | C5: 3 | D5: 46268 | E5: Sí | F5: Hoja de firmas
A6: T002 | B6: PRL-01 | C6: 2 | D6: 45910 | E6: Sí | F6: Hoja de firmas
A7: T003 | B7: PRL-01 | C7: 3 | D7: 46277 | E7: Sí | F7: Hoja de firmas
A8: T004 | B8: PRL-01 | C8: 3 | D8: 46269 | E8: Sí | F8: Hoja de firmas
A9: T005 | B9: PRL-01 | C9: 3 | D9: 46267 | E9: Sí | F9: Hoja de firmas
A10: T006 | B10: PRL-01 | C10: 2 | D10: 45931 | E10: Sí | F10: Hoja de firmas
A11: T007 | B11: PRL-01 | C11: 3 | D11: 46273 | E11: Sí | F11: Hoja de firmas
A12: T008 | B12: PRL-01 | C12: 3 | D12: 46294 | E12: Sí | F12: Hoja de firmas
A13: T002 | B13: PRL-01 | C13: 1 | D13: 45537 | E13: Sí | F13: Hoja de firmas
A14: T006 | B14: PRL-02 | C14: 2 | D14: 45545 | E14: Sí | F14: Hoja de firmas
A15: T007 | B15: PRL-02 | C15: 2 | D15: 46193 | E15: Sí | F15: Hoja de firmas
A16: T004 | B16: PRL-03 | C16: 1 | D16: 45960 | E16: Sí | F16: Hoja de firmas
... A35: T006 | B35: POL-01 | C35: 1 | D35: 46044 | E35: N/A | F35: Hoja de firmas

Sheet Matriz
A1: Matriz de estado (se calcula sola)
A2: No escribas aquí. OK · Pendiente · Caducado · Caduca pronto · «—» no le afecta. Las filas son los trabajadores activos y las columnas las instrucciones.
C4: Instrucción | D4: =IF(Instrucciones!$A$5="","",Instrucciones!$A$5) -> PRL-01 | E4: =IF(Instrucciones!$A$6="","",Instrucciones!$A$6) -> PRL-02 | F4: =IF(Instrucciones!$A$7="","",Instrucciones!$A$7) -> PRL-03 | G4: =IF(Instrucciones!$A$8="","",Instrucciones!$A$8) -> PRL-04 | H4: =IF(Instrucciones!$A$9="","",Instrucciones!$A$9) -> IT-10 | I4: =IF(Instrucciones!$A$10="","",Instrucciones!$A$10) -> IT-11 | J4: =IF(Instrucciones!$A$11="","",Instrucciones!$A$11) -> CAL-01 | K4: =IF(Instrucciones!$A$12="","",Instrucciones!$A$12) -> POL-01 | L4: =IF(Instrucciones!$A$13="","",Instrucciones!$A$13) | M4: =IF(Instrucciones!$A$14="","",Instrucciones!$A$14) | N4: =IF(Instrucciones!$A$15="","",Instrucciones!$A$15) | O4: =IF(Instrucciones!$A$16="","",Instrucciones!$A$16) | P4: =IF(Instrucciones!$A$17="","",Instrucciones!$A$17) | Q4: =IF(Instrucciones!$A$18="","",Instrucciones!$A$18) | R4: =IF(Instrucciones!$A$19="","",Instrucciones!$A$19) | S4: =IF(Instrucciones!$A$20="","",Instrucciones!$A$20) | T4: =IF(Instrucciones!$A$21="","",Instrucciones!$A$21) | U4: =IF(Instrucciones!$A$22="","",Instrucciones!$A$22) | V4: =IF(Instrucciones!$A$23="","",Instrucciones!$A$23) | W4: =IF(Instrucciones!$A$24="","",Instrucciones!$A$24) | X4: =IF(Instrucciones!$A$25="","",Instrucciones!$A$25) | Y4: =IF(Instrucciones!$A$26="","",Instrucciones!$A$26) | Z4: =IF(Instrucciones!$A$27="","",Instrucciones!$A$27) | AA4: =IF(Instrucciones!$A$28="","",Instrucciones!$A$28) | AB4: =IF(Instrucciones!$A$29="","",Instrucciones!$A$29) | AC4: =IF(Instrucciones!$A$30="","",Instrucciones!$A$30) | AD4: =IF(Instrucciones!$A$31="","",Instrucciones!$A$31) | AE4: =IF(Instrucciones!$A$32="","",Instrucciones!$A$32) | AF4: =IF(Instrucciones!$A$33="","",Instrucciones!$A$33) | AG4: =IF(Instrucciones!$A$34="","",Instrucciones!$A$34) | AH4: =IF(Instrucciones!$A$35="","",Instrucciones!$A$35) | AI4: =IF(Instrucciones!$A$36="","",Instrucciones!$A$36) | AJ4: =IF(Instrucciones!$A$37="","",Instrucciones!$A$37) | AK4: =IF(Instrucciones!$A$38="","",Instrucciones!$A$38) | AL4: =IF(Instrucciones!$A$39="","",Instrucciones!$A$39) | AM4: =IF(Instrucciones!$A$40="","",Instrucciones!$A$40) | AN4: =IF(Instrucciones!$A$41="","",Instrucciones!$A$41) | AO4: =IF(Instrucciones!$A$42="","",Instrucciones!$A$42) | AP4: =IF(Instrucciones!$A$43="","",Instrucciones!$A$43) | AQ4: =IF(Instrucciones!$A$44="","",Instrucciones!$A$44)
C5: Versión vigente | D5: =IF(D$4="","",Instrucciones!$D$5) -> 3 | E5: =IF(E$4="","",Instrucciones!$D$6) -> 2 | F5: =IF(F$4="","",Instrucciones!$D$7) -> 1 | G5: =IF(G$4="","",Instrucciones!$D$8) -> 2 | H5: =IF(H$4="","",Instrucciones!$D$9) -> 4 | I5: =IF(I$4="","",Instrucciones!$D$10) -> 2 | J5: =IF(J$4="","",Instrucciones!$D$11) -> 1 | K5: =IF(K$4="","",Instrucciones!$D$12) -> 1 | L5: =IF(L$4="","",Instrucciones!$D$13) | M5: =IF(M$4="","",Instrucciones!$D$14) | N5: =IF(N$4="","",Instrucciones!$D$15) | O5: =IF(O$4="","",Instrucciones!$D$16) | P5: =IF(P$4="","",Instrucciones!$D$17) | Q5: =IF(Q$4="","",Instrucciones!$D$18) | R5: =IF(R$4="","",Instrucciones!$D$19) | S5: =IF(S$4="","",Instrucciones!$D$20) | T5: =IF(T$4="","",Instrucciones!$D$21) | U5: =IF(U$4="","",Instrucciones!$D$22) | V5: =IF(V$4="","",Instrucciones!$D$23) | W5: =IF(W$4="","",Instrucciones!$D$24) | X5: =IF(X$4="","",Instrucciones!$D$25) | Y5: =IF(Y$4="","",Instrucciones!$D$26) | Z5: =IF(Z$4="","",Instrucciones!$D$27) | AA5: =IF(AA$4="","",Instrucciones!$D$28) | AB5: =IF(AB$4="","",Instrucciones!$D$29) | AC5: =IF(AC$4="","",Instrucciones!$D$30) | AD5: =IF(AD$4="","",Instrucciones!$D$31) | AE5: =IF(AE$4="","",Instrucciones!$D$32) | AF5: =IF(AF$4="","",Instrucciones!$D$33) | AG5: =IF(AG$4="","",Instrucciones!$D$34) | AH5: =IF(AH$4="","",Instrucciones!$D$35) | AI5: =IF(AI$4="","",Instrucciones!$D$36) | AJ5: =IF(AJ$4="","",Instrucciones!$D$37) | AK5: =IF(AK$4="","",Instrucciones!$D$38) | AL5: =IF(AL$4="","",Instrucciones!$D$39) | AM5: =IF(AM$4="","",Instrucciones!$D$40) | AN5: =IF(AN$4="","",Instrucciones!$D$41) | AO5: =IF(AO$4="","",Instrucciones!$D$42) | AP5: =IF(AP$4="","",Instrucciones!$D$43) | AQ5: =IF(AQ$4="","",Instrucciones!$D$44)
C6: Alcance | D6: =IF(D$4="","",Instrucciones!$G$5) -> Toda la plantilla | E6: =IF(E$4="","",Instrucciones!$G$6) -> Por puesto | F6: =IF(F$4="","",Instrucciones!$G$7) -> Por puesto | G6: =IF(G$4="","",Instrucciones!$G$8) -> Por puesto | H6: =IF(H$4="","",Instrucciones!$G$9) -> Por puesto | I6: =IF(I$4="","",Instrucciones!$G$10) -> Por puesto | J6: =IF(J$4="","",Instrucciones!$G$11) -> Por puesto | K6: =IF(K$4="","",Instrucciones!$G$12) -> Toda la plantilla | L6: =IF(L$4="","",Instrucciones!$G$13) | M6: =IF(M$4="","",Instrucciones!$G$14) | N6: =IF(N$4="","",Instrucciones!$G$15) | O6: =IF(O$4="","",Instrucciones!$G$16) | P6: =IF(P$4="","",Instrucciones!$G$17) | Q6: =IF(Q$4="","",Instrucciones!$G$18) | R6: =IF(R$4="","",Instrucciones!$G$19) | S6: =IF(S$4="","",Instrucciones!$G$20) | T6: =IF(T$4="","",Instrucciones!$G$21) | U6: =IF(U$4="","",Instrucciones!$G$22) | V6: =IF(V$4="","",Instrucciones!$G$23) | W6: =IF(W$4="","",Instrucciones!$G$24) | X6: =IF(X$4="","",Instrucciones!$G$25) | Y6: =IF(Y$4="","",Instrucciones!$G$26) | Z6: =IF(Z$4="","",Instrucciones!$G$27) | AA6: =IF(AA$4="","",Instrucciones!$G$28) | AB6: =IF(AB$4="","",Instrucciones!$G$29) | AC6: =IF(AC$4="","",Instrucciones!$G$30) | AD6: =IF(AD$4="","",Instrucciones!$G$31) | AE6: =IF(AE$4="","",Instrucciones!$G$32) | AF6: =IF(AF$4="","",Instrucciones!$G$33) | AG6: =IF(AG$4="","",Instrucciones!$G$34) | AH6: =IF(AH$4="","",Instrucciones!$G$35) | AI6: =IF(AI$4="","",Instrucciones!$G$36) | AJ6: =IF(AJ$4="","",Instrucciones!$G$37) | AK6: =IF(AK$4="","",Instrucciones!$G$38) | AL6: =IF(AL$4="","",Instrucciones!$G$39) | AM6: =IF(AM$4="","",Instrucciones!$G$40) | AN6: =IF(AN$4="","",Instrucciones!$G$41) | AO6: =IF(AO$4="","",Instrucciones!$G$42) | AP6: =IF(AP$4="","",Instrucciones!$G$43) | AQ6: =IF(AQ$4="","",Instrucciones!$G$44)
C7: Puestos | D7: =IF(D$4="","",Instrucciones!$H$5&"") | E7: =IF(E$4="","",Instrucciones!$H$6&"") -> Logística; Almacén | F7: =IF(F$4="","",Instrucciones!$H$7&"") -> Mantenimiento; Producción | G7: =IF(G$4="","",Instrucciones!$H$8&"") -> Producción | H7: =IF(H$4="","",Instrucciones!$H$9&"") -> Producción | I7: =IF(I$4="","",Instrucciones!$H$10&"") -> Producción | J7: =IF(J$4="","",Instrucciones!$H$11&"") -> Producción; Calidad | K7: =IF(K$4="","",Instrucciones!$H$12&"") | L7: =IF(L$4="","",Instrucciones!$H$13&"") | M7: =IF(M$4="","",Instrucciones!$H$14&"") | N7: =IF(N$4="","",Instrucciones!$H$15&"") | O7: =IF(O$4="","",Instrucciones!$H$16&"") | P7: =IF(P$4="","",Instrucciones!$H$17&"") | Q7: =IF(Q$4="","",Instrucciones!$H$18&"") | R7: =IF(R$4="","",Instrucciones!$H$19&"") | S7: =IF(S$4="","",Instrucciones!$H$20&"") | T7: =IF(T$4="","",Instrucciones!$H$21&"") | U7: =IF(U$4="","",Instrucciones!$H$22&"") | V7: =IF(V$4="","",Instrucciones!$H$23&"") | W7: =IF(W$4="","",Instrucciones!$H$24&"") | X7: =IF(X$4="","",Instrucciones!$H$25&"") | Y7: =IF(Y$4="","",Instrucciones!$H$26&"") | Z7: =IF(Z$4="","",Instrucciones!$H$27&"") | AA7: =IF(AA$4="","",Instrucciones!$H$28&"") | AB7: =IF(AB$4="","",Instrucciones!$H$29&"") | AC7: =IF(AC$4="","",Instrucciones!$H$30&"") | AD7: =IF(AD$4="","",Instrucciones!$H$31&"") | AE7: =IF(AE$4="","",Instrucciones!$H$32&"") | AF7: =IF(AF$4="","",Instrucciones!$H$33&"") | AG7: =IF(AG$4="","",Instrucciones!$H$34&"") | AH7: =IF(AH$4="","",Instrucciones!$H$35&"") | AI7: =IF(AI$4="","",Instrucciones!$H$36&"") | AJ7: =IF(AJ$4="","",Instrucciones!$H$37&"") | AK7: =IF(AK$4="","",Instrucciones!$H$38&"") | AL7: =IF(AL$4="","",Instrucciones!$H$39&"") | AM7: =IF(AM$4="","",Instrucciones!$H$40&"") | AN7: =IF(AN$4="","",Instrucciones!$H$41&"") | AO7: =IF(AO$4="","",Instrucciones!$H$42&"") | AP7: =IF(AP$4="","",Instrucciones!$H$43&"") | AQ7: =IF(AQ$4="","",Instrucciones!$H$44&"")
C8: Reciclaje (meses) | D8: =IF(D$4="","",N(Instrucciones!$I$5)) -> 12 | E8: =IF(E$4="","",N(Instrucciones!$I$6)) -> 24 | F8: =IF(F$4="","",N(Instrucciones!$I$7)) -> 12 | G8: =IF(G$4="","",N(Instrucciones!$I$8)) -> 0 | H8: =IF(H$4="","",N(Instrucciones!$I$9)) -> 0 | I8: =IF(I$4="","",N(Instrucciones!$I$10)) -> 0 | J8: =IF(J$4="","",N(Instrucciones!$I$11)) -> 0 | K8: =IF(K$4="","",N(Instrucciones!$I$12)) -> 0 | L8: =IF(L$4="","",N(Instrucciones!$I$13)) | M8: =IF(M$4="","",N(Instrucciones!$I$14)) | N8: =IF(N$4="","",N(Instrucciones!$I$15)) | O8: =IF(O$4="","",N(Instrucciones!$I$16)) | P8: =IF(P$4="","",N(Instrucciones!$I$17)) | Q8: =IF(Q$4="","",N(Instrucciones!$I$18)) | R8: =IF(R$4="","",N(Instrucciones!$I$19)) | S8: =IF(S$4="","",N(Instrucciones!$I$20)) | T8: =IF(T$4="","",N(Instrucciones!$I$21)) | U8: =IF(U$4="","",N(Instrucciones!$I$22)) | V8: =IF(V$4="","",N(Instrucciones!$I$23)) | W8: =IF(W$4="","",N(Instrucciones!$I$24)) | X8: =IF(X$4="","",N(Instrucciones!$I$25)) | Y8: =IF(Y$4="","",N(Instrucciones!$I$26)) | Z8: =IF(Z$4="","",N(Instrucciones!$I$27)) | AA8: =IF(AA$4="","",N(Instrucciones!$I$28)) | AB8: =IF(AB$4="","",N(Instrucciones!$I$29)) | AC8: =IF(AC$4="","",N(Instrucciones!$I$30)) | AD8: =IF(AD$4="","",N(Instrucciones!$I$31)) | AE8: =IF(AE$4="","",N(Instrucciones!$I$32)) | AF8: =IF(AF$4="","",N(Instrucciones!$I$33)) | AG8: =IF(AG$4="","",N(Instrucciones!$I$34)) | AH8: =IF(AH$4="","",N(Instrucciones!$I$35)) | AI8: =IF(AI$4="","",N(Instrucciones!$I$36)) | AJ8: =IF(AJ$4="","",N(Instrucciones!$I$37)) | AK8: =IF(AK$4="","",N(Instrucciones!$I$38)) | AL8: =IF(AL$4="","",N(Instrucciones!$I$39)) | AM8: =IF(AM$4="","",N(Instrucciones!$I$40)) | AN8: =IF(AN$4="","",N(Instrucciones!$I$41)) | AO8: =IF(AO$4="","",N(Instrucciones!$I$42)) | AP8: =IF(AP$4="","",N(Instrucciones!$I$43)) | AQ8: =IF(AQ$4="","",N(Instrucciones!$I$44))
A9: ID | B9: Nombre | C9: Puesto
A10: =IF(AND(Trabajadores!$A$5<>"",Trabajadores!$G$5<>"No"),Trabajadores!$A$5,"") -> T001 | B10: =IF($A10="","",Trabajadores!$B$5) -> Ana López | C10: =IF($A10="","",Trabajadores!$C$5) -> Producción | D10: =IF(OR($A10="",D$4=""),"",IF(NOT(OR(D$6="Toda la plantilla",ISNUMBER(SEARCH(";"&SUBSTITUTE($C10," ","")&";",";"&SUBSTITUTE(D$7," ","")&";")))),"—",IF(_xlfn.MAXIFS(Acuses!$C$5:$C$3004,Acuses!$A$5:$A$3004,$A10,Acuses!$B$5:$B$3004,D$4)<D$5,"Pendiente",IF(D$8=0,"OK",IF(EDATE(_xlfn.MAXIFS(Acuses!$D$5:$D$3004,Acuses!$A$5:$A$3004,$A10,Acuses!$B$5:$B$3004,D$4,Acuses!$C$5:$C$3004,D$5),D$8)<Resumen!$C$4,"Caducado",IF(EDATE(_xlfn.MAXIFS(Acuses!$D$5:$D$3004,Acuses!$A$5:$A$3004,$A10,Acuses!$B$5:$B$3004,D$4,Acuses!$C$5:$C$3004,D$5),D$8)<Resumen!$C$4+30,"Caduca pronto","OK")))))) -> OK | E10: =IF(OR($A10="",E$4=""),"",IF(NOT(OR(E$6="Toda la plantilla",ISNUMBER(SEARCH(";"&SUBSTITUTE($C10," ","")&";",";"&SUBSTITUTE(E$7," ","")&";")))),"—",IF(_xlfn.MAXIFS(Acuses!$C$5:$C$3004,Acuses!$A$5:$A$3004,$A10,Acuses!$B$5:$B$3004,E$4)<E$5,"Pendiente",IF(E$8=0,"OK",IF(EDATE(_xlfn.MAXIFS(Acuses!$D$5:$D$3004,Acuses!$A$5:$A$3004,$A10,Acuses!$B$5:$B$3004,E$4,Acuses!$C$5:$C$3004,E$5),E$8)<Resumen!$C$4,"Caducado",IF(EDATE(_xlfn.MAXIFS(Acuses!$D$5:$D$3004,Acuses!$A$5:$A$3004,$A10,Acuses!$B$5:$B$3004,E$4,Acuses!$C$5:$C$3004,E$5),E$8)<Resumen!$C$4+30,"Caduca pronto","OK")))))) -> — | F10: =IF(OR($A10="",F$4=""),"",IF(NOT(OR(F$6="Toda la plantilla",ISNUMBER(SEARCH(";"&SUBSTITUTE($C10," ","")&";",";"&SUBSTITUTE(F$7," ","")&";")))),"—",IF(_xlfn.MAXIFS(Acuses!$C$5:$C$3004,Acuses!$A$5:$A$3004,$A10,Acuses!$B$5:$B$3004,F$4)<F$5,"Pendiente",IF(F$8=0,"OK",IF(EDATE(_xlfn.MAXIFS(Acuses!$D$5:$D$3004,Acuses!$A$5:$A$3004,$A10,Acuses!$B$5:$B$3004,F$4,Acuses!$C$5:$C$3004,F$5),F$8)<Resumen!$C$4,"Caducado",IF(EDATE(_xlfn.MAXIFS(Acuses!$D$5:$D$3004,Acuses!$A$5:$A$3004,$A10,Acuses!$B$5:$B$3004,F$4,Acuses!$C$5:$C$3004,F$5),F$8)<Resumen!$C$4+30,"Caduca pronto","OK")))))) -> OK | G10: =IF(OR($A10="",G$4=""),"",IF(NOT(OR(G$6="Toda la plantilla",ISNUMBER(SEARCH(";"&SUBSTITUTE($C10," ","")&";",";"&SUBSTITUTE(G$7," ","")&";")))),"—",IF(_xlfn.MAXIFS(Acuses!$C$5:$C$3004,Acuses!$A$5:$A$3004,$A10,Acuses!$B$5:$B$3004,G$4)<G$5,"Pendiente",IF(G$8=0,"OK",IF(EDATE(_xlfn.MAXIFS(Acuses!$D$5:$D$3004,Acuses!$A$5:$A$3004,$A10,Acuses!$B$5:$B$3004,G$4,Acuses!$C$5:$C$3004,G$5),G$8)<Resumen!$C$4,"Caducado",IF(EDATE(_xlfn.MAXIFS(Acuses!$D$5:$D$3004,Acuses!$A$5:$A$3004,$A10,Acuses!$B$5:$B$3004,G$4,Acuses!$C$5:$C$3004,G$5),G$8)<Resumen!$C$4+30,"Caduca pronto","OK")))))) -> OK | H10: =IF(OR($A10="",H$4=""),"",IF(NOT(OR(H$6="Toda la plantilla",ISNUMBER(SEARCH(";"&SUBSTITUTE($C10," ","")&";",";"&SUBSTITUTE(H$7," ","")&";")))),"—",IF(_xlfn.MAXIFS(Acuses!$C$5:$C$3004,Acuses!$A$5:$A$3004,$A10,Acuses!$B$5:$B$3004,H$4)<H$5,"Pendiente",IF(H$8=0,"OK",IF(EDATE(_xlfn.MAXIFS(Acuses!$D$5:$D$3004,Acuses!$A$5:$A$3004,$A10,Acuses!$B$5:$B$3004,H$4,Acuses!$C$5:$C$3004,H$5),H$8)<Resumen!$C$4,"Caducado",IF(EDATE(_xlfn.MAXIFS(Acuses!$D$5:$D$3004,Acuses!$A$5:$A$3004,$A10,Acuses!$B$5:$B$3004,H$4,Acuses!$C$5:$C$3004,H$5),H$8)<Resumen!$C$4+30,"Caduca pronto","OK")))))) -> OK | I10: =IF(OR($A10="",I$4=""),"",IF(NOT(OR(I$6="Toda la plantilla",ISNUMBER(SEARCH(";"&SUBSTITUTE($C10," ","")&";",";"&SUBSTITUTE(I$7," ","")&";")))),"—",IF(_xlfn.MAXIFS(Acuses!$C$5:$C$3004,Acuses!$A$5:$A$3004,$A10,Acuses!$B$5:$B$3004,I$4)<I$5,"Pendiente",IF(I$8=0,"OK",IF(EDATE(_xlfn.MAXIFS(Acuses!$D$5:$D$3004,Acuses!$A$5:$A$3004,$A10,Acuses!$B$5:$B$3004,I$4,Acuses!$C$5:$C$3004,I$5),I$8)<Resumen!$C$4,"Caducado",IF(EDATE(_xlfn.MAXIFS(Acuses!$D$5:$D$3004,Acuses!$A$5:$A$3004,$A10,Acuses!$B$5:$B$3004,I$4,Acuses!$C$5:$C$3004,I$5),I$8)<Resumen!$C$4+30,"Caduca pronto","OK")))))) -> OK | J10: =IF(OR($A10="",J$4=""),"",IF(NOT(OR(J$6="Toda la plantilla",ISNUMBER(SEARCH(";"&SUBSTITUTE($C10," ","")&";",";"&SUBSTITUTE(J$7," ","")&";")))),"—",IF(_xlfn.MAXIFS(Acuses!$C$5:$C$3004,Acuses!$A$5:$A$3004,$A10,Acuses!$B$5:$B$3004,J$4)<J$5,"Pendiente",IF(J$8=0,"OK",IF(EDATE(_xlfn.MAXIFS(Acuses!$D$5:$D$3004,Acuses!$A$5:$A$3004,$A10,Acuses!$B$5:$B$3004,J$4,Acuses!$C$5:$C$3004,J$5),J$8)<Resumen!$C$4,"Caducado",IF(EDATE(_xlfn.MAXIFS(Acuses!$D$5:$D$3004,Acuses!$A$5:$A$3004,$A10,Acuses!$B$5:$B$3004,J$4,Acuses!$C$5:$C$3004,J$5),J$8)<Resumen!$C$4+30,"Caduca pronto","OK")))))) -> OK | K10: =IF(OR($A10="",K$4=""),"",IF(NOT(OR(K$6="Toda la plantilla",ISNUMBER(SEARCH(";"&SUBSTITUTE($C10," ","")&";",";"&SUBSTITUTE(K$7," ","")&";")))),"—",IF(_xlfn.MAXIFS(Acuses!$C$5:$C$3004,Acuses!$A$5:$A$3004,$A10,Acuses!$B$5:$B$3004,K$4)<K$5,"Pendiente",IF(K$8=0,"OK",IF(EDATE(_xlfn.MAXIFS(Acuses!$D$5:$D$3004,Acuses!$A$5:$A$3004,$A10,Acuses!$B$5:$B$3004,K$4,Acuses!$C$5:$C$3004,K$5),K$8)<Resumen!$C$4,"Caducado",IF(EDATE(_xlfn.MAXIFS(Acuses!$D$5:$D$3004,Acuses!$A$5:$A$3004,$A10,Acuses!$B$5:$B$3004,K$4,Acuses!$C$5:$C$3004,K$5),K$8)<Resumen!$C$4+30,"Caduca pronto","OK")))))) -> OK | ... AQ10: =IF(OR($A10="",AQ$4=""),"",IF(NOT(OR(AQ$6="Toda la plantilla",ISNUMBER(SEARCH(";"&SUBSTITUTE($C10," ","")&";",";"&SUBSTITUTE(AQ$7," ","")&";")))),"—",IF(_xlfn.MAXIFS(Acuses!$C$5:$C$3004,Acuses!$A$5:$A$3004,$A10,Acuses!$B$5:$B$3004,AQ$4)<AQ$5,"Pendiente",IF(AQ$8=0,"OK",IF(EDATE(_xlfn.MAXIFS(Acuses!$D$5:$D$3004,Acuses!$A$5:$A$3004,$A10,Acuses!$B$5:$B$3004,AQ$4,Acuses!$C$5:$C$3004,AQ$5),AQ$8)<Resumen!$C$4,"Caducado",IF(EDATE(_xlfn.MAXIFS(Acuses!$D$5:$D$3004,Acuses!$A$5:$A$3004,$A10,Acuses!$B$5:$B$3004,AQ$4,Acuses!$C$5:$C$3004,AQ$5),AQ$8)<Resumen!$C$4+30,"Caduca pronto","OK"))))))
A11: =IF(AND(Trabajadores!$A$6<>"",Trabajadores!$G$6<>"No"),Trabajadores!$A$6,"") -> T002 | B11: =IF($A11="","",Trabajadores!$B$6) -> Carlos Ruiz | C11: =IF($A11="","",Trabajadores!$C$6) -> Producción | D11: =IF(OR($A11="",D$4=""),"",IF(NOT(OR(D$6="Toda la plantilla",ISNUMBER(SEARCH(";"&SUBSTITUTE($C11," ","")&";",";"&SUBSTITUTE(D$7," ","")&";")))),"—",IF(_xlfn.MAXIFS(Acuses!$C$5:$C$3004,Acuses!$A$5:$A$3004,$A11,Acuses!$B$5:$B$3004,D$4)<D$5,"Pendiente",IF(D$8=0,"OK",IF(EDATE(_xlfn.MAXIFS(Acuses!$D$5:$D$3004,Acuses!$A$5:$A$3004,$A11,Acuses!$B$5:$B$3004,D$4,Acuses!$C$5:$C$3004,D$5),D$8)<Resumen!$C$4,"Caducado",IF(EDATE(_xlfn.MAXIFS(Acuses!$D$5:$D$3004,Acuses!$A$5:$A$3004,$A11,Acuses!$B$5:$B$3004,D$4,Acuses!$C$5:$C$3004,D$5),D$8)<Resumen!$C$4+30,"Caduca pronto","OK")))))) -> Pendiente | E11: =IF(OR($A11="",E$4=""),"",IF(NOT(OR(E$6="Toda la plantilla",ISNUMBER(SEARCH(";"&SUBSTITUTE($C11," ","")&";",";"&SUBSTITUTE(E$7," ","")&";")))),"—",IF(_xlfn.MAXIFS(Acuses!$C$5:$C$3004,Acuses!$A$5:$A$3004,$A11,Acuses!$B$5:$B$3004,E$4)<E$5,"Pendiente",IF(E$8=0,"OK",IF(EDATE(_xlfn.MAXIFS(Acuses!$D$5:$D$3004,Acuses!$A$5:$A$3004,$A11,Acuses!$B$5:$B$3004,E$4,Acuses!$C$5:$C$3004,E$5),E$8)<Resumen!$C$4,"Caducado",IF(EDATE(_xlfn.MAXIFS(Acuses!$D$5:$D$3004,Acuses!$A$5:$A$3004,$A11,Acuses!$B$5:$B$3004,E$4,Acuses!$C$5:$C$3004,E$5),E$8)<Resumen!$C$4+30,"Caduca pronto","OK")))))) -> — | F11: =IF(OR($A11="",F$4=""),"",IF(NOT(OR(F$6="Toda la plantilla",ISNUMBER(SEARCH(";"&SUBSTITUTE($C11," ","")&";",";"&SUBSTITUTE(F$7," ","")&";")))),"—",IF(_xlfn.MAXIFS(Acuses!$C$5:$C$3004,Acuses!$A$5:$A$3004,$A11,Acuses!$B$5:$B$3004,F$4)<F$5,"Pendiente",IF(F$8=0,"OK",IF(EDATE(_xlfn.MAXIFS(Acuses!$D$5:$D$3004,Acuses!$A$5:$A$3004,$A11,Acuses!$B$5:$B$3004,F$4,Acuses!$C$5:$C$3004,F$5),F$8)<Resumen!$C$4,"Caducado",IF(EDATE(_xlfn.MAXIFS(Acuses!$D$5:$D$3004,Acuses!$A$5:$A$3004,$A11,Acuses!$B$5:$B$3004,F$4,Acuses!$C$5:$C$3004,F$5),F$8)<Resumen!$C$4+30,"Caduca pronto","OK")))))) -> OK | G11: =IF(OR($A11="",G$4=""),"",IF(NOT(OR(G$6="Toda la plantilla",ISNUMBER(SEARCH(";"&SUBSTITUTE($C11," ","")&";",";"&SUBSTITUTE(G$7," ","")&";")))),"—",IF(_xlfn.MAXIFS(Acuses!$C$5:$C$3004,Acuses!$A$5:$A$3004,$A11,Acuses!$B$5:$B$3004,G$4)<G$5,"Pendiente",IF(G$8=0,"OK",IF(EDATE(_xlfn.MAXIFS(Acuses!$D$5:$D$3004,Acuses!$A$5:$A$3004,$A11,Acuses!$B$5:$B$3004,G$4,Acuses!$C$5:$C$3004,G$5),G$8)<Resumen!$C$4,"Caducado",IF(EDATE(_xlfn.MAXIFS(Acuses!$D$5:$D$3004,Acuses!$A$5:$A$3004,$A11,Acuses!$B$5:$B$3004,G$4,Acuses!$C$5:$C$3004,G$5),G$8)<Resumen!$C$4+30,"Caduca pronto","OK")))))) -> Pendiente | H11: =IF(OR($A11="",H$4=""),"",IF(NOT(OR(H$6="Toda la plantilla",ISNUMBER(SEARCH(";"&SUBSTITUTE($C11," ","")&";",";"&SUBSTITUTE(H$7," ","")&";")))),"—",IF(_xlfn.MAXIFS(Acuses!$C$5:$C$3004,Acuses!$A$5:$A$3004,$A11,Acuses!$B$5:$B$3004,H$4)<H$5,"Pendiente",IF(H$8=0,"OK",IF(EDATE(_xlfn.MAXIFS(Acuses!$D$5:$D$3004,Acuses!$A$5:$A$3004,$A11,Acuses!$B$5:$B$3004,H$4,Acuses!$C$5:$C$3004,H$5),H$8)<Resumen!$C$4,"Caducado",IF(EDATE(_xlfn.MAXIFS(Acuses!$D$5:$D$3004,Acuses!$A$5:$A$3004,$A11,Acuses!$B$5:$B$3004,H$4,Acuses!$C$5:$C$3004,H$5),H$8)<Resumen!$C$4+30,"Caduca pronto","OK")))))) -> Pendiente | I11: =IF(OR($A11="",I$4=""),"",IF(NOT(OR(I$6="Toda la plantilla",ISNUMBER(SEARCH(";"&SUBSTITUTE($C11," ","")&";",";"&SUBSTITUTE(I$7," ","")&";")))),"—",IF(_xlfn.MAXIFS(Acuses!$C$5:$C$3004,Acuses!$A$5:$A$3004,$A11,Acuses!$B$5:$B$3004,I$4)<I$5,"Pendiente",IF(I$8=0,"OK",IF(EDATE(_xlfn.MAXIFS(Acuses!$D$5:$D$3004,Acuses!$A$5:$A$3004,$A11,Acuses!$B$5:$B$3004,I$4,Acuses!$C$5:$C$3004,I$5),I$8)<Resumen!$C$4,"Caducado",IF(EDATE(_xlfn.MAXIFS(Acuses!$D$5:$D$3004,Acuses!$A$5:$A$3004,$A11,Acuses!$B$5:$B$3004,I$4,Acuses!$C$5:$C$3004,I$5),I$8)<Resumen!$C$4+30,"Caduca pronto","OK")))))) -> OK | J11: =IF(OR($A11="",J$4=""),"",IF(NOT(OR(J$6="Toda la plantilla",ISNUMBER(SEARCH(";"&SUBSTITUTE($C11," ","")&";",";"&SUBSTITUTE(J$7," ","")&";")))),"—",IF(_xlfn.MAXIFS(Acuses!$C$5:$C$3004,Acuses!$A$5:$A$3004,$A11,Acuses!$B$5:$B$3004,J$4)<J$5,"Pendiente",IF(J$8=0,"OK",IF(EDATE(_xlfn.MAXIFS(Acuses!$D$5:$D$3004,Acuses!$A$5:$A$3004,$A11,Acuses!$B$5:$B$3004,J$4,Acuses!$C$5:$C$3004,J$5),J$8)<Resumen!$C$4,"Caducado",IF(EDATE(_xlfn.MAXIFS(Acuses!$D$5:$D$3004,Acuses!$A$5:$A$3004,$A11,Acuses!$B$5:$B$3004,J$4,Acuses!$C$5:$C$3004,J$5),J$8)<Resumen!$C$4+30,"Caduca pronto","OK")))))) -> Pendiente | K11: =IF(OR($A11="",K$4=""),"",IF(NOT(OR(K$6="Toda la plantilla",ISNUMBER(SEARCH(";"&SUBSTITUTE($C11," ","")&";",";"&SUBSTITUTE(K$7," ","")&";")))),"—",IF(_xlfn.MAXIFS(Acuses!$C$5:$C$3004,Acuses!$A$5:$A$3004,$A11,Acuses!$B$5:$B$3004,K$4)<K$5,"Pendiente",IF(K$8=0,"OK",IF(EDATE(_xlfn.MAXIFS(Acuses!$D$5:$D$3004,Acuses!$A$5:$A$3004,$A11,Acuses!$B$5:$B$3004,K$4,Acuses!$C$5:$C$3004,K$5),K$8)<Resumen!$C$4,"Caducado",IF(EDATE(_xlfn.MAXIFS(Acuses!$D$5:$D$3004,Acuses!$A$5:$A$3004,$A11,Acuses!$B$5:$B$3004,K$4,Acuses!$C$5:$C$3004,K$5),K$8)<Resumen!$C$4+30,"Caduca pronto","OK")))))) -> OK | ... AQ11: =IF(OR($A11="",AQ$4=""),"",IF(NOT(OR(AQ$6="Toda la plantilla",ISNUMBER(SEARCH(";"&SUBSTITUTE($C11," ","")&";",";"&SUBSTITUTE(AQ$7," ","")&";")))),"—",IF(_xlfn.MAXIFS(Acuses!$C$5:$C$3004,Acuses!$A$5:$A$3004,$A11,Acuses!$B$5:$B$3004,AQ$4)<AQ$5,"Pendiente",IF(AQ$8=0,"OK",IF(EDATE(_xlfn.MAXIFS(Acuses!$D$5:$D$3004,Acuses!$A$5:$A$3004,$A11,Acuses!$B$5:$B$3004,AQ$4,Acuses!$C$5:$C$3004,AQ$5),AQ$8)<Resumen!$C$4,"Caducado",IF(EDATE(_xlfn.MAXIFS(Acuses!$D$5:$D$3004,Acuses!$A$5:$A$3004,$A11,Acuses!$B$5:$B$3004,AQ$4,Acuses!$C$5:$C$3004,AQ$5),AQ$8)<Resumen!$C$4+30,"Caduca pronto","OK"))))))
A12: =IF(AND(Trabajadores!$A$7<>"",Trabajadores!$G$7<>"No"),Trabajadores!$A$7,"") -> T003 | B12: =IF($A12="","",Trabajadores!$B$7) -> Marta Gil | C12: =IF($A12="","",Trabajadores!$C$7) -> Producción | D12: =IF(OR($A12="",D$4=""),"",IF(NOT(OR(D$6="Toda la plantilla",ISNUMBER(SEARCH(";"&SUBSTITUTE($C12," ","")&";",";"&SUBSTITUTE(D$7," ","")&";")))),"—",IF(_xlfn.MAXIFS(Acuses!$C$5:$C$3004,Acuses!$A$5:$A$3004,$A12,Acuses!$B$5:$B$3004,D$4)<D$5,"Pendiente",IF(D$8=0,"OK",IF(EDATE(_xlfn.MAXIFS(Acuses!$D$5:$D$3004,Acuses!$A$5:$A$3004,$A12,Acuses!$B$5:$B$3004,D$4,Acuses!$C$5:$C$3004,D$5),D$8)<Resumen!$C$4,"Caducado",IF(EDATE(_xlfn.MAXIFS(Acuses!$D$5:$D$3004,Acuses!$A$5:$A$3004,$A12,Acuses!$B$5:$B$3004,D$4,Acuses!$C$5:$C$3004,D$5),D$8)<Resumen!$C$4+30,"Caduca pronto","OK")))))) -> OK | E12: =IF(OR($A12="",E$4=""),"",IF(NOT(OR(E$6="Toda la plantilla",ISNUMBER(SEARCH(";"&SUBSTITUTE($C12," ","")&";",";"&SUBSTITUTE(E$7," ","")&";")))),"—",IF(_xlfn.MAXIFS(Acuses!$C$5:$C$3004,Acuses!$A$5:$A$3004,$A12,Acuses!$B$5:$B$3004,E$4)<E$5,"Pendiente",IF(E$8=0,"OK",IF(EDATE(_xlfn.MAXIFS(Acuses!$D$5:$D$3004,Acuses!$A$5:$A$3004,$A12,Acuses!$B$5:$B$3004,E$4,Acuses!$C$5:$C$3004,E$5),E$8)<Resumen!$C$4,"Caducado",IF(EDATE(_xlfn.MAXIFS(Acuses!$D$5:$D$3004,Acuses!$A$5:$A$3004,$A12,Acuses!$B$5:$B$3004,E$4,Acuses!$C$5:$C$3004,E$5),E$8)<Resumen!$C$4+30,"Caduca pronto","OK")))))) -> — | F12: =IF(OR($A12="",F$4=""),"",IF(NOT(OR(F$6="Toda la plantilla",ISNUMBER(SEARCH(";"&SUBSTITUTE($C12," ","")&";",";"&SUBSTITUTE(F$7," ","")&";")))),"—",IF(_xlfn.MAXIFS(Acuses!$C$5:$C$3004,Acuses!$A$5:$A$3004,$A12,Acuses!$B$5:$B$3004,F$4)<F$5,"Pendiente",IF(F$8=0,"OK",IF(EDATE(_xlfn.MAXIFS(Acuses!$D$5:$D$3004,Acuses!$A$5:$A$3004,$A12,Acuses!$B$5:$B$3004,F$4,Acuses!$C$5:$C$3004,F$5),F$8)<Resumen!$C$4,"Caducado",IF(EDATE(_xlfn.MAXIFS(Acuses!$D$5:$D$3004,Acuses!$A$5:$A$3004,$A12,Acuses!$B$5:$B$3004,F$4,Acuses!$C$5:$C$3004,F$5),F$8)<Resumen!$C$4+30,"Caduca pronto","OK")))))) -> Pendiente | G12: =IF(OR($A12="",G$4=""),"",IF(NOT(OR(G$6="Toda la plantilla",ISNUMBER(SEARCH(";"&SUBSTITUTE($C12," ","")&";",";"&SUBSTITUTE(G$7," ","")&";")))),"—",IF(_xlfn.MAXIFS(Acuses!$C$5:$C$3004,Acuses!$A$5:$A$3004,$A12,Acuses!$B$5:$B$3004,G$4)<G$5,"Pendiente",IF(G$8=0,"OK",IF(EDATE(_xlfn.MAXIFS(Acuses!$D$5:$D$3004,Acuses!$A$5:$A$3004,$A12,Acuses!$B$5:$B$3004,G$4,Acuses!$C$5:$C$3004,G$5),G$8)<Resumen!$C$4,"Caducado",IF(EDATE(_xlfn.MAXIFS(Acuses!$D$5:$D$3004,Acuses!$A$5:$A$3004,$A12,Acuses!$B$5:$B$3004,G$4,Acuses!$C$5:$C$3004,G$5),G$8)<Resumen!$C$4+30,"Caduca pronto","OK")))))) -> OK | H12: =IF(OR($A12="",H$4=""),"",IF(NOT(OR(H$6="Toda la plantilla",ISNUMBER(SEARCH(";"&SUBSTITUTE($C12," ","")&";",";"&SUBSTITUTE(H$7," ","")&";")))),"—",IF(_xlfn.MAXIFS(Acuses!$C$5:$C$3004,Acuses!$A$5:$A$3004,$A12,Acuses!$B$5:$B$3004,H$4)<H$5,"Pendiente",IF(H$8=0,"OK",IF(EDATE(_xlfn.MAXIFS(Acuses!$D$5:$D$3004,Acuses!$A$5:$A$3004,$A12,Acuses!$B$5:$B$3004,H$4,Acuses!$C$5:$C$3004,H$5),H$8)<Resumen!$C$4,"Caducado",IF(EDATE(_xlfn.MAXIFS(Acuses!$D$5:$D$3004,Acuses!$A$5:$A$3004,$A12,Acuses!$B$5:$B$3004,H$4,Acuses!$C$5:$C$3004,H$5),H$8)<Resumen!$C$4+30,"Caduca pronto","OK")))))) -> Pendiente | I12: =IF(OR($A12="",I$4=""),"",IF(NOT(OR(I$6="Toda la plantilla",ISNUMBER(SEARCH(";"&SUBSTITUTE($C12," ","")&";",";"&SUBSTITUTE(I$7," ","")&";")))),"—",IF(_xlfn.MAXIFS(Acuses!$C$5:$C$3004,Acuses!$A$5:$A$3004,$A12,Acuses!$B$5:$B$3004,I$4)<I$5,"Pendiente",IF(I$8=0,"OK",IF(EDATE(_xlfn.MAXIFS(Acuses!$D$5:$D$3004,Acuses!$A$5:$A$3004,$A12,Acuses!$B$5:$B$3004,I$4,Acuses!$C$5:$C$3004,I$5),I$8)<Resumen!$C$4,"Caducado",IF(EDATE(_xlfn.MAXIFS(Acuses!$D$5:$D$3004,Acuses!$A$5:$A$3004,$A12,Acuses!$B$5:$B$3004,I$4,Acuses!$C$5:$C$3004,I$5),I$8)<Resumen!$C$4+30,"Caduca pronto","OK")))))) -> OK | J12: =IF(OR($A12="",J$4=""),"",IF(NOT(OR(J$6="Toda la plantilla",ISNUMBER(SEARCH(";"&SUBSTITUTE($C12," ","")&";",";"&SUBSTITUTE(J$7," ","")&";")))),"—",IF(_xlfn.MAXIFS(Acuses!$C$5:$C$3004,Acuses!$A$5:$A$3004,$A12,Acuses!$B$5:$B$3004,J$4)<J$5,"Pendiente",IF(J$8=0,"OK",IF(EDATE(_xlfn.MAXIFS(Acuses!$D$5:$D$3004,Acuses!$A$5:$A$3004,$A12,Acuses!$B$5:$B$3004,J$4,Acuses!$C$5:$C$3004,J$5),J$8)<Resumen!$C$4,"Caducado",IF(EDATE(_xlfn.MAXIFS(Acuses!$D$5:$D$3004,Acuses!$A$5:$A$3004,$A12,Acuses!$B$5:$B$3004,J$4,Acuses!$C$5:$C$3004,J$5),J$8)<Resumen!$C$4+30,"Caduca pronto","OK")))))) -> Pendiente | K12: =IF(OR($A12="",K$4=""),"",IF(NOT(OR(K$6="Toda la plantilla",ISNUMBER(SEARCH(";"&SUBSTITUTE($C12," ","")&";",";"&SUBSTITUTE(K$7," ","")&";")))),"—",IF(_xlfn.MAXIFS(Acuses!$C$5:$C$3004,Acuses!$A$5:$A$3004,$A12,Acuses!$B$5:$B$3004,K$4)<K$5,"Pendiente",IF(K$8=0,"OK",IF(EDATE(_xlfn.MAXIFS(Acuses!$D$5:$D$3004,Acuses!$A$5:$A$3004,$A12,Acuses!$B$5:$B$3004,K$4,Acuses!$C$5:$C$3004,K$5),K$8)<Resumen!$C$4,"Caducado",IF(EDATE(_xlfn.MAXIFS(Acuses!$D$5:$D$3004,Acuses!$A$5:$A$3004,$A12,Acuses!$B$5:$B$3004,K$4,Acuses!$C$5:$C$3004,K$5),K$8)<Resumen!$C$4+30,"Caduca pronto","OK")))))) -> Pendiente | ... AQ12: =IF(OR($A12="",AQ$4=""),"",IF(NOT(OR(AQ$6="Toda la plantilla",ISNUMBER(SEARCH(";"&SUBSTITUTE($C12," ","")&";",";"&SUBSTITUTE(AQ$7," ","")&";")))),"—",IF(_xlfn.MAXIFS(Acuses!$C$5:$C$3004,Acuses!$A$5:$A$3004,$A12,Acuses!$B$5:$B$3004,AQ$4)<AQ$5,"Pendiente",IF(AQ$8=0,"OK",IF(EDATE(_xlfn.MAXIFS(Acuses!$D$5:$D$3004,Acuses!$A$5:$A$3004,$A12,Acuses!$B$5:$B$3004,AQ$4,Acuses!$C$5:$C$3004,AQ$5),AQ$8)<Resumen!$C$4,"Caducado",IF(EDATE(_xlfn.MAXIFS(Acuses!$D$5:$D$3004,Acuses!$A$5:$A$3004,$A12,Acuses!$B$5:$B$3004,AQ$4,Acuses!$C$5:$C$3004,AQ$5),AQ$8)<Resumen!$C$4+30,"Caduca pronto","OK"))))))
